2023-04-13 21:53:14 [   DEBUG] Looking for locale `en_US` in provider `faker.providers.address`. (factory.py:79)
2023-04-13 21:53:14 [   DEBUG] Provider `faker.providers.address` has been localized to `en_US`. (factory.py:98)
2023-04-13 21:53:14 [   DEBUG] Looking for locale `en_US` in provider `faker.providers.automotive`. (factory.py:79)
2023-04-13 21:53:14 [   DEBUG] Provider `faker.providers.automotive` has been localized to `en_US`. (factory.py:98)
2023-04-13 21:53:14 [   DEBUG] Looking for locale `en_US` in provider `faker.providers.bank`. (factory.py:79)
2023-04-13 21:53:14 [   DEBUG] Specified locale `en_US` is not available for provider `faker.providers.bank`. Locale reset to `en_GB` for this provider. (factory.py:92)
2023-04-13 21:53:14 [   DEBUG] Looking for locale `en_US` in provider `faker.providers.barcode`. (factory.py:79)
2023-04-13 21:53:14 [   DEBUG] Provider `faker.providers.barcode` has been localized to `en_US`. (factory.py:98)
2023-04-13 21:53:14 [   DEBUG] Looking for locale `en_US` in provider `faker.providers.color`. (factory.py:79)
2023-04-13 21:53:14 [   DEBUG] Provider `faker.providers.color` has been localized to `en_US`. (factory.py:98)
2023-04-13 21:53:14 [   DEBUG] Looking for locale `en_US` in provider `faker.providers.company`. (factory.py:79)
2023-04-13 21:53:14 [   DEBUG] Provider `faker.providers.company` has been localized to `en_US`. (factory.py:98)
2023-04-13 21:53:14 [   DEBUG] Looking for locale `en_US` in provider `faker.providers.credit_card`. (factory.py:79)
2023-04-13 21:53:14 [   DEBUG] Provider `faker.providers.credit_card` has been localized to `en_US`. (factory.py:98)
2023-04-13 21:53:14 [   DEBUG] Looking for locale `en_US` in provider `faker.providers.currency`. (factory.py:79)
2023-04-13 21:53:14 [   DEBUG] Provider `faker.providers.currency` has been localized to `en_US`. (factory.py:98)
2023-04-13 21:53:14 [   DEBUG] Looking for locale `en_US` in provider `faker.providers.date_time`. (factory.py:79)
2023-04-13 21:53:14 [   DEBUG] Provider `faker.providers.date_time` has been localized to `en_US`. (factory.py:98)
2023-04-13 21:53:14 [   DEBUG] Provider `faker.providers.emoji` does not feature localization. Specified locale `en_US` is not utilized for this provider. (factory.py:111)
2023-04-13 21:53:14 [   DEBUG] Provider `faker.providers.file` does not feature localization. Specified locale `en_US` is not utilized for this provider. (factory.py:111)
2023-04-13 21:53:14 [   DEBUG] Looking for locale `en_US` in provider `faker.providers.geo`. (factory.py:79)
2023-04-13 21:53:14 [   DEBUG] Provider `faker.providers.geo` has been localized to `en_US`. (factory.py:98)
2023-04-13 21:53:14 [   DEBUG] Looking for locale `en_US` in provider `faker.providers.internet`. (factory.py:79)
2023-04-13 21:53:14 [   DEBUG] Provider `faker.providers.internet` has been localized to `en_US`. (factory.py:98)
2023-04-13 21:53:14 [   DEBUG] Provider `faker.providers.isbn` does not feature localization. Specified locale `en_US` is not utilized for this provider. (factory.py:111)
2023-04-13 21:53:14 [   DEBUG] Looking for locale `en_US` in provider `faker.providers.job`. (factory.py:79)
2023-04-13 21:53:14 [   DEBUG] Provider `faker.providers.job` has been localized to `en_US`. (factory.py:98)
2023-04-13 21:53:14 [   DEBUG] Looking for locale `en_US` in provider `faker.providers.lorem`. (factory.py:79)
2023-04-13 21:53:14 [   DEBUG] Provider `faker.providers.lorem` has been localized to `en_US`. (factory.py:98)
2023-04-13 21:53:14 [   DEBUG] Looking for locale `en_US` in provider `faker.providers.misc`. (factory.py:79)
2023-04-13 21:53:14 [   DEBUG] Provider `faker.providers.misc` has been localized to `en_US`. (factory.py:98)
2023-04-13 21:53:14 [   DEBUG] Looking for locale `en_US` in provider `faker.providers.person`. (factory.py:79)
2023-04-13 21:53:14 [   DEBUG] Provider `faker.providers.person` has been localized to `en_US`. (factory.py:98)
2023-04-13 21:53:14 [   DEBUG] Looking for locale `en_US` in provider `faker.providers.phone_number`. (factory.py:79)
2023-04-13 21:53:14 [   DEBUG] Provider `faker.providers.phone_number` has been localized to `en_US`. (factory.py:98)
2023-04-13 21:53:14 [   DEBUG] Provider `faker.providers.profile` does not feature localization. Specified locale `en_US` is not utilized for this provider. (factory.py:111)
2023-04-13 21:53:14 [   DEBUG] Provider `faker.providers.python` does not feature localization. Specified locale `en_US` is not utilized for this provider. (factory.py:111)
2023-04-13 21:53:14 [   DEBUG] Provider `faker.providers.sbn` does not feature localization. Specified locale `en_US` is not utilized for this provider. (factory.py:111)
2023-04-13 21:53:14 [   DEBUG] Looking for locale `en_US` in provider `faker.providers.ssn`. (factory.py:79)
2023-04-13 21:53:14 [   DEBUG] Provider `faker.providers.ssn` has been localized to `en_US`. (factory.py:98)
2023-04-13 21:53:14 [   DEBUG] Provider `faker.providers.user_agent` does not feature localization. Specified locale `en_US` is not utilized for this provider. (factory.py:111)
2023-04-13 21:53:14 [   DEBUG] Request: GET https://console-dev.cf/api/customer-manager/v2/admin/customers (client.py:184)
2023-04-13 21:53:14 [   DEBUG] Starting new HTTPS connection (1): test.iam.rnd.4cloud.cf:443 (connectionpool.py:1007)
2023-04-13 21:53:16 [   DEBUG] Request: GET https://console-dev.cf/api/customer-manager/v2/admin/customers/497fcf40-e10a-417d-a8bc-41b3f737a1ce (client.py:184)
2023-04-13 21:53:16 [   DEBUG] Starting new HTTPS connection (1): test.iam.rnd.4cloud.cf:443 (connectionpool.py:1007)
2023-04-13 21:53:16 [   DEBUG] Request: PATCH https://console-dev.cf/api/customer-manager/v2/admin/customers/2117e508-d285-4e75-9e5a-485949229fbb (client.py:184)
2023-04-13 21:53:16 [   DEBUG] Starting new HTTPS connection (1): test.iam.rnd.4cloud.cf:443 (connectionpool.py:1007)
2023-04-13 21:53:17 [   DEBUG] Request: GET https://console-dev.cf/api/customer-manager/v2/customers/me (client.py:184)
2023-04-13 21:53:17 [   DEBUG] Starting new HTTPS connection (1): test.iam.rnd.4cloud.cf:443 (connectionpool.py:1007)
2023-04-13 21:53:17 [   DEBUG] Request: GET https://console-dev.cf/api/iam/v1/users/me (client.py:184)
2023-04-13 21:53:17 [   DEBUG] Starting new HTTPS connection (1): test.iam.rnd.4cloud.cf:443 (connectionpool.py:1007)
2023-04-13 21:53:17 [   DEBUG] Request: GET https://console-dev.cf/api/iam/v2/customers/2117e508-d285-4e75-9e5a-485949229fbb (client.py:184)
2023-04-13 21:53:17 [   DEBUG] Starting new HTTPS connection (1): test.iam.rnd.4cloud.cf:443 (connectionpool.py:1007)
2023-04-13 21:53:18 [   DEBUG] Request: GET https://console-dev.cf/api/iam/v2/customers/2117e508-d285-4e75-9e5a-485949229fbb/folders (client.py:184)
2023-04-13 21:53:18 [   DEBUG] Starting new HTTPS connection (1): test.iam.rnd.4cloud.cf:443 (connectionpool.py:1007)
2023-04-13 21:53:18 [   DEBUG] Request: GET https://console-dev.cf/api/iam/v2/customers/1234/folders (client.py:184)
2023-04-13 21:53:18 [   DEBUG] Starting new HTTPS connection (1): test.iam.rnd.4cloud.cf:443 (connectionpool.py:1007)
2023-04-13 21:53:18 [   DEBUG] Request: GET https://console-dev.cf/api/iam/v2/customers/2117e508-d285-4e75-9e5a-485949229fbb/permissions (client.py:184)
2023-04-13 21:53:18 [   DEBUG] Starting new HTTPS connection (1): test.iam.rnd.4cloud.cf:443 (connectionpool.py:1007)
2023-04-13 21:53:18 [   DEBUG] Request: GET https://console-dev.cf/api/iam/v2/customers/2117e508-d285-4e75-9e5a-485949229fbb/projects (client.py:184)
2023-04-13 21:53:18 [   DEBUG] Starting new HTTPS connection (1): test.iam.rnd.4cloud.cf:443 (connectionpool.py:1007)
2023-04-13 21:53:18 [   DEBUG] Request: POST https://console-dev.cf/api/iam/v2/customers (client.py:184)
2023-04-13 21:53:18 [   DEBUG] Request body: {'customer_id': '2117e508-1112-4e75-9e5a-485949229fbb', 'display_name': 'TEMP-CUSTOMER'} (client.py:186)
2023-04-13 21:53:18 [   DEBUG] Starting new HTTPS connection (1): test.iam.rnd.4cloud.cf:443 (connectionpool.py:1007)
2023-04-13 21:53:18 [   DEBUG] Request: PATCH https://console-dev.cf/api/iam/v2/customers/2117e508-1112-4e75-9e5a-485949229fbb (client.py:184)
2023-04-13 21:53:18 [   DEBUG] Request body: {'customer_id': '2117e508-1112-4e75-9e5a-485949229fbb', 'params': {'display_name': '123123123'}} (client.py:186)
2023-04-13 21:53:18 [   DEBUG] Starting new HTTPS connection (1): test.iam.rnd.4cloud.cf:443 (connectionpool.py:1007)
2023-04-13 21:53:19 [   DEBUG] Request: DELETE https://console-dev.cf/api/iam/v2/customers/2117e508-1112-4e75-9e5a-485949229fbb (client.py:184)
2023-04-13 21:53:19 [   DEBUG] Starting new HTTPS connection (1): test.iam.rnd.4cloud.cf:443 (connectionpool.py:1007)
2023-04-13 21:53:19 [   DEBUG] Request: GET https://console-dev.cf/api/iam/v2/users/me (client.py:184)
2023-04-13 21:53:19 [   DEBUG] Starting new HTTPS connection (1): test.iam.rnd.4cloud.cf:443 (connectionpool.py:1007)
2023-04-13 21:53:19 [   DEBUG] Request: GET https://console-dev.cf/api/iam/v2/users/me/permissions (client.py:184)
2023-04-13 21:53:19 [   DEBUG] Starting new HTTPS connection (1): test.iam.rnd.4cloud.cf:443 (connectionpool.py:1007)
2023-04-13 21:53:19 [   DEBUG] Request: GET https://console-dev.cf/api/iam/v2/users/me/permissions/project/scopes?objects=d8e26141-4791-4a40-aec7-44f7bf3f7f0b (client.py:184)
2023-04-13 21:53:19 [   DEBUG] Starting new HTTPS connection (1): test.iam.rnd.4cloud.cf:443 (connectionpool.py:1007)
2023-04-13 21:53:19 [   DEBUG] Request: GET https://console-dev.cf/api/iam/v2/users/fa8043b5-b65b-410e-af5c-0f8ae4fb7ba1 (client.py:184)
2023-04-13 21:53:19 [   DEBUG] Starting new HTTPS connection (1): test.iam.rnd.4cloud.cf:443 (connectionpool.py:1007)
2023-04-13 21:53:19 [   DEBUG] Request: GET https://console-dev.cf/api/iam/v2/users/fa8043b5-b65b-410e-af5c-0f8ae4fb7ba1/permissions (client.py:184)
2023-04-13 21:53:19 [   DEBUG] Starting new HTTPS connection (1): test.iam.rnd.4cloud.cf:443 (connectionpool.py:1007)
2023-04-13 21:53:19 [   DEBUG] Request: GET https://console-dev.cf/api/iam/v2/users/fa8043b5-b65b-410e-af5c-0f8ae4fb7ba1/permissions/project/scopes?objects=d8e26141-4791-4a40-aec7-44f7bf3f7f0b (client.py:184)
2023-04-13 21:53:19 [   DEBUG] Starting new HTTPS connection (1): test.iam.rnd.4cloud.cf:443 (connectionpool.py:1007)
2023-04-13 21:53:20 [   DEBUG] Request: GET https://console-dev.cf/api/order-manager/v1/orders/25159794-c58e-456a-bc0c-06774dcd1bc7 (client.py:184)
2023-04-13 21:53:20 [   DEBUG] Starting new HTTPS connection (1): test.iam.rnd.4cloud.cf:443 (connectionpool.py:1007)
2023-04-13 21:53:20 [   DEBUG] Request: GET https://console-dev.cf/api/order-manager/v1/tasks (client.py:184)
2023-04-13 21:53:20 [   DEBUG] Starting new HTTPS connection (1): test.iam.rnd.4cloud.cf:443 (connectionpool.py:1007)
2023-04-13 21:53:20 [   DEBUG] Request: GET https://console-dev.cf/api/order-manager/v1/tasks/19f85c68-f5e8-49e2-ac26-c17ab33c7b2a (client.py:184)
2023-04-13 21:53:20 [   DEBUG] Starting new HTTPS connection (1): test.iam.rnd.4cloud.cf:443 (connectionpool.py:1007)
2023-04-13 21:53:20 [   DEBUG] POST http://localhost:4444/wd/hub/session {"capabilities": {"firstMatch": [{}], "alwaysMatch": {"browserName": "chrome", "platformName": "any", "goog:chromeOptions": {"binary": "", "args": ["--window-size=1920,1080"]}}}} (remote_connection.py:303)
2023-04-13 21:53:20 [   DEBUG] Starting new HTTP connection (1): localhost:4444 (connectionpool.py:232)
2023-04-13 21:53:20 [   DEBUG] Incremented Retry for (url='/wd/hub/session'): Retry(total=2, connect=None, read=None, redirect=None, status=None) (retry.py:594)
2023-04-13 21:53:20 [ WARNING] Retrying (Retry(total=2, connect=None, read=None, redirect=None, status=None)) after connection broken by 'NewConnectionError('<urllib3.connection.HTTPConnection object at 0x1128edc90>: Failed to establish a new connection: [Errno 61] Connection refused')': /wd/hub/session (connectionpool.py:813)
2023-04-13 21:53:20 [   DEBUG] Starting new HTTP connection (2): localhost:4444 (connectionpool.py:232)
2023-04-13 21:53:20 [   DEBUG] Incremented Retry for (url='/wd/hub/session'): Retry(total=1, connect=None, read=None, redirect=None, status=None) (retry.py:594)
2023-04-13 21:53:20 [ WARNING] Retrying (Retry(total=1, connect=None, read=None, redirect=None, status=None)) after connection broken by 'NewConnectionError('<urllib3.connection.HTTPConnection object at 0x1129016d0>: Failed to establish a new connection: [Errno 61] Connection refused')': /wd/hub/session (connectionpool.py:813)
2023-04-13 21:53:20 [   DEBUG] Starting new HTTP connection (3): localhost:4444 (connectionpool.py:232)
2023-04-13 21:53:20 [   DEBUG] Incremented Retry for (url='/wd/hub/session'): Retry(total=0, connect=None, read=None, redirect=None, status=None) (retry.py:594)
2023-04-13 21:53:20 [ WARNING] Retrying (Retry(total=0, connect=None, read=None, redirect=None, status=None)) after connection broken by 'NewConnectionError('<urllib3.connection.HTTPConnection object at 0x112901650>: Failed to establish a new connection: [Errno 61] Connection refused')': /wd/hub/session (connectionpool.py:813)
2023-04-13 21:53:20 [   DEBUG] Starting new HTTP connection (4): localhost:4444 (connectionpool.py:232)
2023-04-13 21:53:20 [   DEBUG] POST http://localhost:4444/wd/hub/session {"capabilities": {"firstMatch": [{}], "alwaysMatch": {"browserName": "chrome", "platformName": "any", "goog:chromeOptions": {"binary": "", "args": ["--window-size=1920,1080"]}}}} (remote_connection.py:303)
2023-04-13 21:53:20 [   DEBUG] Starting new HTTP connection (1): localhost:4444 (connectionpool.py:232)
2023-04-13 21:53:20 [   DEBUG] Incremented Retry for (url='/wd/hub/session'): Retry(total=2, connect=None, read=None, redirect=None, status=None) (retry.py:594)
2023-04-13 21:53:20 [ WARNING] Retrying (Retry(total=2, connect=None, read=None, redirect=None, status=None)) after connection broken by 'NewConnectionError('<urllib3.connection.HTTPConnection object at 0x112c70c90>: Failed to establish a new connection: [Errno 61] Connection refused')': /wd/hub/session (connectionpool.py:813)
2023-04-13 21:53:20 [   DEBUG] Starting new HTTP connection (2): localhost:4444 (connectionpool.py:232)
2023-04-13 21:53:20 [   DEBUG] Incremented Retry for (url='/wd/hub/session'): Retry(total=1, connect=None, read=None, redirect=None, status=None) (retry.py:594)
2023-04-13 21:53:20 [ WARNING] Retrying (Retry(total=1, connect=None, read=None, redirect=None, status=None)) after connection broken by 'NewConnectionError('<urllib3.connection.HTTPConnection object at 0x11293d550>: Failed to establish a new connection: [Errno 61] Connection refused')': /wd/hub/session (connectionpool.py:813)
2023-04-13 21:53:20 [   DEBUG] Starting new HTTP connection (3): localhost:4444 (connectionpool.py:232)
2023-04-13 21:53:20 [   DEBUG] Incremented Retry for (url='/wd/hub/session'): Retry(total=0, connect=None, read=None, redirect=None, status=None) (retry.py:594)
2023-04-13 21:53:20 [ WARNING] Retrying (Retry(total=0, connect=None, read=None, redirect=None, status=None)) after connection broken by 'NewConnectionError('<urllib3.connection.HTTPConnection object at 0x11293f9d0>: Failed to establish a new connection: [Errno 61] Connection refused')': /wd/hub/session (connectionpool.py:813)
2023-04-13 21:53:20 [   DEBUG] Starting new HTTP connection (4): localhost:4444 (connectionpool.py:232)
2023-04-13 21:53:21 [   DEBUG] POST http://localhost:4444/wd/hub/session {"capabilities": {"firstMatch": [{}], "alwaysMatch": {"browserName": "chrome", "platformName": "any", "goog:chromeOptions": {"binary": "", "args": ["--window-size=1920,1080"]}}}} (remote_connection.py:303)
2023-04-13 21:53:21 [   DEBUG] Starting new HTTP connection (1): localhost:4444 (connectionpool.py:232)
2023-04-13 21:53:21 [   DEBUG] Incremented Retry for (url='/wd/hub/session'): Retry(total=2, connect=None, read=None, redirect=None, status=None) (retry.py:594)
2023-04-13 21:53:21 [ WARNING] Retrying (Retry(total=2, connect=None, read=None, redirect=None, status=None)) after connection broken by 'NewConnectionError('<urllib3.connection.HTTPConnection object at 0x112c7add0>: Failed to establish a new connection: [Errno 61] Connection refused')': /wd/hub/session (connectionpool.py:813)
2023-04-13 21:53:21 [   DEBUG] Starting new HTTP connection (2): localhost:4444 (connectionpool.py:232)
2023-04-13 21:53:21 [   DEBUG] Incremented Retry for (url='/wd/hub/session'): Retry(total=1, connect=None, read=None, redirect=None, status=None) (retry.py:594)
2023-04-13 21:53:21 [ WARNING] Retrying (Retry(total=1, connect=None, read=None, redirect=None, status=None)) after connection broken by 'NewConnectionError('<urllib3.connection.HTTPConnection object at 0x1127e9e90>: Failed to establish a new connection: [Errno 61] Connection refused')': /wd/hub/session (connectionpool.py:813)
2023-04-13 21:53:21 [   DEBUG] Starting new HTTP connection (3): localhost:4444 (connectionpool.py:232)
2023-04-13 21:53:21 [   DEBUG] Incremented Retry for (url='/wd/hub/session'): Retry(total=0, connect=None, read=None, redirect=None, status=None) (retry.py:594)
2023-04-13 21:53:21 [ WARNING] Retrying (Retry(total=0, connect=None, read=None, redirect=None, status=None)) after connection broken by 'NewConnectionError('<urllib3.connection.HTTPConnection object at 0x1127e9990>: Failed to establish a new connection: [Errno 61] Connection refused')': /wd/hub/session (connectionpool.py:813)
2023-04-13 21:53:21 [   DEBUG] Starting new HTTP connection (4): localhost:4444 (connectionpool.py:232)
2023-04-13 21:53:21 [   DEBUG] POST http://localhost:4444/wd/hub/session {"capabilities": {"firstMatch": [{}], "alwaysMatch": {"browserName": "chrome", "platformName": "any", "goog:chromeOptions": {"binary": "", "args": ["--window-size=1920,1080"]}}}} (remote_connection.py:303)
2023-04-13 21:53:21 [   DEBUG] Starting new HTTP connection (1): localhost:4444 (connectionpool.py:232)
2023-04-13 21:53:21 [   DEBUG] Incremented Retry for (url='/wd/hub/session'): Retry(total=2, connect=None, read=None, redirect=None, status=None) (retry.py:594)
2023-04-13 21:53:21 [ WARNING] Retrying (Retry(total=2, connect=None, read=None, redirect=None, status=None)) after connection broken by 'NewConnectionError('<urllib3.connection.HTTPConnection object at 0x112cb77d0>: Failed to establish a new connection: [Errno 61] Connection refused')': /wd/hub/session (connectionpool.py:813)
2023-04-13 21:53:21 [   DEBUG] Starting new HTTP connection (2): localhost:4444 (connectionpool.py:232)
2023-04-13 21:53:21 [   DEBUG] Incremented Retry for (url='/wd/hub/session'): Retry(total=1, connect=None, read=None, redirect=None, status=None) (retry.py:594)
2023-04-13 21:53:21 [ WARNING] Retrying (Retry(total=1, connect=None, read=None, redirect=None, status=None)) after connection broken by 'NewConnectionError('<urllib3.connection.HTTPConnection object at 0x112cb7d90>: Failed to establish a new connection: [Errno 61] Connection refused')': /wd/hub/session (connectionpool.py:813)
2023-04-13 21:53:21 [   DEBUG] Starting new HTTP connection (3): localhost:4444 (connectionpool.py:232)
2023-04-13 21:53:21 [   DEBUG] Incremented Retry for (url='/wd/hub/session'): Retry(total=0, connect=None, read=None, redirect=None, status=None) (retry.py:594)
2023-04-13 21:53:21 [ WARNING] Retrying (Retry(total=0, connect=None, read=None, redirect=None, status=None)) after connection broken by 'NewConnectionError('<urllib3.connection.HTTPConnection object at 0x112c3a610>: Failed to establish a new connection: [Errno 61] Connection refused')': /wd/hub/session (connectionpool.py:813)
2023-04-13 21:53:21 [   DEBUG] Starting new HTTP connection (4): localhost:4444 (connectionpool.py:232)
2023-04-13 21:53:21 [   DEBUG] POST http://localhost:4444/wd/hub/session {"capabilities": {"firstMatch": [{}], "alwaysMatch": {"browserName": "chrome", "platformName": "any", "goog:chromeOptions": {"binary": "", "args": ["--window-size=1920,1080"]}}}} (remote_connection.py:303)
2023-04-13 21:53:21 [   DEBUG] Starting new HTTP connection (1): localhost:4444 (connectionpool.py:232)
2023-04-13 21:53:21 [   DEBUG] Incremented Retry for (url='/wd/hub/session'): Retry(total=2, connect=None, read=None, redirect=None, status=None) (retry.py:594)
2023-04-13 21:53:21 [ WARNING] Retrying (Retry(total=2, connect=None, read=None, redirect=None, status=None)) after connection broken by 'NewConnectionError('<urllib3.connection.HTTPConnection object at 0x1128d8f10>: Failed to establish a new connection: [Errno 61] Connection refused')': /wd/hub/session (connectionpool.py:813)
2023-04-13 21:53:21 [   DEBUG] Starting new HTTP connection (2): localhost:4444 (connectionpool.py:232)
2023-04-13 21:53:21 [   DEBUG] Incremented Retry for (url='/wd/hub/session'): Retry(total=1, connect=None, read=None, redirect=None, status=None) (retry.py:594)
2023-04-13 21:53:21 [ WARNING] Retrying (Retry(total=1, connect=None, read=None, redirect=None, status=None)) after connection broken by 'NewConnectionError('<urllib3.connection.HTTPConnection object at 0x112874610>: Failed to establish a new connection: [Errno 61] Connection refused')': /wd/hub/session (connectionpool.py:813)
2023-04-13 21:53:21 [   DEBUG] Starting new HTTP connection (3): localhost:4444 (connectionpool.py:232)
2023-04-13 21:53:21 [   DEBUG] Incremented Retry for (url='/wd/hub/session'): Retry(total=0, connect=None, read=None, redirect=None, status=None) (retry.py:594)
2023-04-13 21:53:21 [ WARNING] Retrying (Retry(total=0, connect=None, read=None, redirect=None, status=None)) after connection broken by 'NewConnectionError('<urllib3.connection.HTTPConnection object at 0x112874a10>: Failed to establish a new connection: [Errno 61] Connection refused')': /wd/hub/session (connectionpool.py:813)
2023-04-13 21:53:21 [   DEBUG] Starting new HTTP connection (4): localhost:4444 (connectionpool.py:232)
2023-04-13 21:53:22 [   DEBUG] POST http://localhost:4444/wd/hub/session {"capabilities": {"firstMatch": [{}], "alwaysMatch": {"browserName": "chrome", "platformName": "any", "goog:chromeOptions": {"binary": "", "args": ["--window-size=1920,1080"]}}}} (remote_connection.py:303)
2023-04-13 21:53:22 [   DEBUG] Starting new HTTP connection (1): localhost:4444 (connectionpool.py:232)
2023-04-13 21:53:22 [   DEBUG] Incremented Retry for (url='/wd/hub/session'): Retry(total=2, connect=None, read=None, redirect=None, status=None) (retry.py:594)
2023-04-13 21:53:22 [ WARNING] Retrying (Retry(total=2, connect=None, read=None, redirect=None, status=None)) after connection broken by 'NewConnectionError('<urllib3.connection.HTTPConnection object at 0x1124c7c50>: Failed to establish a new connection: [Errno 61] Connection refused')': /wd/hub/session (connectionpool.py:813)
2023-04-13 21:53:22 [   DEBUG] Starting new HTTP connection (2): localhost:4444 (connectionpool.py:232)
2023-04-13 21:53:22 [   DEBUG] Incremented Retry for (url='/wd/hub/session'): Retry(total=1, connect=None, read=None, redirect=None, status=None) (retry.py:594)
2023-04-13 21:53:22 [ WARNING] Retrying (Retry(total=1, connect=None, read=None, redirect=None, status=None)) after connection broken by 'NewConnectionError('<urllib3.connection.HTTPConnection object at 0x112c8de10>: Failed to establish a new connection: [Errno 61] Connection refused')': /wd/hub/session (connectionpool.py:813)
2023-04-13 21:53:22 [   DEBUG] Starting new HTTP connection (3): localhost:4444 (connectionpool.py:232)
2023-04-13 21:53:22 [   DEBUG] Incremented Retry for (url='/wd/hub/session'): Retry(total=0, connect=None, read=None, redirect=None, status=None) (retry.py:594)
2023-04-13 21:53:22 [ WARNING] Retrying (Retry(total=0, connect=None, read=None, redirect=None, status=None)) after connection broken by 'NewConnectionError('<urllib3.connection.HTTPConnection object at 0x112c8d450>: Failed to establish a new connection: [Errno 61] Connection refused')': /wd/hub/session (connectionpool.py:813)
2023-04-13 21:53:22 [   DEBUG] Starting new HTTP connection (4): localhost:4444 (connectionpool.py:232)
2023-04-13 21:53:22 [   DEBUG] POST http://localhost:4444/wd/hub/session {"capabilities": {"firstMatch": [{}], "alwaysMatch": {"browserName": "chrome", "platformName": "any", "goog:chromeOptions": {"binary": "", "args": ["--window-size=1920,1080"]}}}} (remote_connection.py:303)
2023-04-13 21:53:22 [   DEBUG] Starting new HTTP connection (1): localhost:4444 (connectionpool.py:232)
2023-04-13 21:53:22 [   DEBUG] Incremented Retry for (url='/wd/hub/session'): Retry(total=2, connect=None, read=None, redirect=None, status=None) (retry.py:594)
2023-04-13 21:53:22 [ WARNING] Retrying (Retry(total=2, connect=None, read=None, redirect=None, status=None)) after connection broken by 'NewConnectionError('<urllib3.connection.HTTPConnection object at 0x112c33f50>: Failed to establish a new connection: [Errno 61] Connection refused')': /wd/hub/session (connectionpool.py:813)
2023-04-13 21:53:22 [   DEBUG] Starting new HTTP connection (2): localhost:4444 (connectionpool.py:232)
2023-04-13 21:53:22 [   DEBUG] Incremented Retry for (url='/wd/hub/session'): Retry(total=1, connect=None, read=None, redirect=None, status=None) (retry.py:594)
2023-04-13 21:53:22 [ WARNING] Retrying (Retry(total=1, connect=None, read=None, redirect=None, status=None)) after connection broken by 'NewConnectionError('<urllib3.connection.HTTPConnection object at 0x112607bd0>: Failed to establish a new connection: [Errno 61] Connection refused')': /wd/hub/session (connectionpool.py:813)
2023-04-13 21:53:22 [   DEBUG] Starting new HTTP connection (3): localhost:4444 (connectionpool.py:232)
2023-04-13 21:53:22 [   DEBUG] Incremented Retry for (url='/wd/hub/session'): Retry(total=0, connect=None, read=None, redirect=None, status=None) (retry.py:594)
2023-04-13 21:53:22 [ WARNING] Retrying (Retry(total=0, connect=None, read=None, redirect=None, status=None)) after connection broken by 'NewConnectionError('<urllib3.connection.HTTPConnection object at 0x112c3a090>: Failed to establish a new connection: [Errno 61] Connection refused')': /wd/hub/session (connectionpool.py:813)
2023-04-13 21:53:22 [   DEBUG] Starting new HTTP connection (4): localhost:4444 (connectionpool.py:232)
2023-04-13 21:53:22 [   DEBUG] POST http://localhost:4444/wd/hub/session {"capabilities": {"firstMatch": [{}], "alwaysMatch": {"browserName": "chrome", "platformName": "any", "goog:chromeOptions": {"binary": "", "args": ["--window-size=1920,1080"]}}}} (remote_connection.py:303)
2023-04-13 21:53:22 [   DEBUG] Starting new HTTP connection (1): localhost:4444 (connectionpool.py:232)
2023-04-13 21:53:22 [   DEBUG] Incremented Retry for (url='/wd/hub/session'): Retry(total=2, connect=None, read=None, redirect=None, status=None) (retry.py:594)
2023-04-13 21:53:22 [ WARNING] Retrying (Retry(total=2, connect=None, read=None, redirect=None, status=None)) after connection broken by 'NewConnectionError('<urllib3.connection.HTTPConnection object at 0x112dd0a50>: Failed to establish a new connection: [Errno 61] Connection refused')': /wd/hub/session (connectionpool.py:813)
2023-04-13 21:53:22 [   DEBUG] Starting new HTTP connection (2): localhost:4444 (connectionpool.py:232)
2023-04-13 21:53:22 [   DEBUG] Incremented Retry for (url='/wd/hub/session'): Retry(total=1, connect=None, read=None, redirect=None, status=None) (retry.py:594)
2023-04-13 21:53:22 [ WARNING] Retrying (Retry(total=1, connect=None, read=None, redirect=None, status=None)) after connection broken by 'NewConnectionError('<urllib3.connection.HTTPConnection object at 0x112dd0f90>: Failed to establish a new connection: [Errno 61] Connection refused')': /wd/hub/session (connectionpool.py:813)
2023-04-13 21:53:22 [   DEBUG] Starting new HTTP connection (3): localhost:4444 (connectionpool.py:232)
2023-04-13 21:53:22 [   DEBUG] Incremented Retry for (url='/wd/hub/session'): Retry(total=0, connect=None, read=None, redirect=None, status=None) (retry.py:594)
2023-04-13 21:53:22 [ WARNING] Retrying (Retry(total=0, connect=None, read=None, redirect=None, status=None)) after connection broken by 'NewConnectionError('<urllib3.connection.HTTPConnection object at 0x1128ece90>: Failed to establish a new connection: [Errno 61] Connection refused')': /wd/hub/session (connectionpool.py:813)
2023-04-13 21:53:22 [   DEBUG] Starting new HTTP connection (4): localhost:4444 (connectionpool.py:232)
2023-04-13 21:53:22 [   DEBUG] POST http://localhost:4444/wd/hub/session {"capabilities": {"firstMatch": [{}], "alwaysMatch": {"browserName": "chrome", "platformName": "any", "goog:chromeOptions": {"binary": "", "args": ["--window-size=1920,1080"]}}}} (remote_connection.py:303)
2023-04-13 21:53:22 [   DEBUG] Starting new HTTP connection (1): localhost:4444 (connectionpool.py:232)
2023-04-13 21:53:22 [   DEBUG] Incremented Retry for (url='/wd/hub/session'): Retry(total=2, connect=None, read=None, redirect=None, status=None) (retry.py:594)
2023-04-13 21:53:22 [ WARNING] Retrying (Retry(total=2, connect=None, read=None, redirect=None, status=None)) after connection broken by 'NewConnectionError('<urllib3.connection.HTTPConnection object at 0x112890c50>: Failed to establish a new connection: [Errno 61] Connection refused')': /wd/hub/session (connectionpool.py:813)
2023-04-13 21:53:22 [   DEBUG] Starting new HTTP connection (2): localhost:4444 (connectionpool.py:232)
2023-04-13 21:53:22 [   DEBUG] Incremented Retry for (url='/wd/hub/session'): Retry(total=1, connect=None, read=None, redirect=None, status=None) (retry.py:594)
2023-04-13 21:53:22 [ WARNING] Retrying (Retry(total=1, connect=None, read=None, redirect=None, status=None)) after connection broken by 'NewConnectionError('<urllib3.connection.HTTPConnection object at 0x112626d10>: Failed to establish a new connection: [Errno 61] Connection refused')': /wd/hub/session (connectionpool.py:813)
2023-04-13 21:53:22 [   DEBUG] Starting new HTTP connection (3): localhost:4444 (connectionpool.py:232)
2023-04-13 21:53:22 [   DEBUG] Incremented Retry for (url='/wd/hub/session'): Retry(total=0, connect=None, read=None, redirect=None, status=None) (retry.py:594)
2023-04-13 21:53:22 [ WARNING] Retrying (Retry(total=0, connect=None, read=None, redirect=None, status=None)) after connection broken by 'NewConnectionError('<urllib3.connection.HTTPConnection object at 0x1126267d0>: Failed to establish a new connection: [Errno 61] Connection refused')': /wd/hub/session (connectionpool.py:813)
2023-04-13 21:53:22 [   DEBUG] Starting new HTTP connection (4): localhost:4444 (connectionpool.py:232)
2023-04-13 21:53:23 [   DEBUG] POST http://localhost:4444/wd/hub/session {"capabilities": {"firstMatch": [{}], "alwaysMatch": {"browserName": "chrome", "platformName": "any", "goog:chromeOptions": {"binary": "", "args": ["--window-size=1920,1080"]}}}} (remote_connection.py:303)
2023-04-13 21:53:23 [   DEBUG] Starting new HTTP connection (1): localhost:4444 (connectionpool.py:232)
2023-04-13 21:53:23 [   DEBUG] Incremented Retry for (url='/wd/hub/session'): Retry(total=2, connect=None, read=None, redirect=None, status=None) (retry.py:594)
2023-04-13 21:53:23 [ WARNING] Retrying (Retry(total=2, connect=None, read=None, redirect=None, status=None)) after connection broken by 'NewConnectionError('<urllib3.connection.HTTPConnection object at 0x112c516d0>: Failed to establish a new connection: [Errno 61] Connection refused')': /wd/hub/session (connectionpool.py:813)
2023-04-13 21:53:23 [   DEBUG] Starting new HTTP connection (2): localhost:4444 (connectionpool.py:232)
2023-04-13 21:53:23 [   DEBUG] Incremented Retry for (url='/wd/hub/session'): Retry(total=1, connect=None, read=None, redirect=None, status=None) (retry.py:594)
2023-04-13 21:53:23 [ WARNING] Retrying (Retry(total=1, connect=None, read=None, redirect=None, status=None)) after connection broken by 'NewConnectionError('<urllib3.connection.HTTPConnection object at 0x112e761d0>: Failed to establish a new connection: [Errno 61] Connection refused')': /wd/hub/session (connectionpool.py:813)
2023-04-13 21:53:23 [   DEBUG] Starting new HTTP connection (3): localhost:4444 (connectionpool.py:232)
2023-04-13 21:53:23 [   DEBUG] Incremented Retry for (url='/wd/hub/session'): Retry(total=0, connect=None, read=None, redirect=None, status=None) (retry.py:594)
2023-04-13 21:53:23 [ WARNING] Retrying (Retry(total=0, connect=None, read=None, redirect=None, status=None)) after connection broken by 'NewConnectionError('<urllib3.connection.HTTPConnection object at 0x112e76590>: Failed to establish a new connection: [Errno 61] Connection refused')': /wd/hub/session (connectionpool.py:813)
2023-04-13 21:53:23 [   DEBUG] Starting new HTTP connection (4): localhost:4444 (connectionpool.py:232)
2023-04-13 21:53:23 [   DEBUG] POST http://localhost:4444/wd/hub/session {"capabilities": {"firstMatch": [{}], "alwaysMatch": {"browserName": "chrome", "platformName": "any", "goog:chromeOptions": {"binary": "", "args": ["--window-size=1920,1080"]}}}} (remote_connection.py:303)
2023-04-13 21:53:23 [   DEBUG] Starting new HTTP connection (1): localhost:4444 (connectionpool.py:232)
2023-04-13 21:53:23 [   DEBUG] Incremented Retry for (url='/wd/hub/session'): Retry(total=2, connect=None, read=None, redirect=None, status=None) (retry.py:594)
2023-04-13 21:53:23 [ WARNING] Retrying (Retry(total=2, connect=None, read=None, redirect=None, status=None)) after connection broken by 'NewConnectionError('<urllib3.connection.HTTPConnection object at 0x112969810>: Failed to establish a new connection: [Errno 61] Connection refused')': /wd/hub/session (connectionpool.py:813)
2023-04-13 21:53:23 [   DEBUG] Starting new HTTP connection (2): localhost:4444 (connectionpool.py:232)
2023-04-13 21:53:23 [   DEBUG] Incremented Retry for (url='/wd/hub/session'): Retry(total=1, connect=None, read=None, redirect=None, status=None) (retry.py:594)
2023-04-13 21:53:23 [ WARNING] Retrying (Retry(total=1, connect=None, read=None, redirect=None, status=None)) after connection broken by 'NewConnectionError('<urllib3.connection.HTTPConnection object at 0x112969d10>: Failed to establish a new connection: [Errno 61] Connection refused')': /wd/hub/session (connectionpool.py:813)
2023-04-13 21:53:23 [   DEBUG] Starting new HTTP connection (3): localhost:4444 (connectionpool.py:232)
2023-04-13 21:53:23 [   DEBUG] Incremented Retry for (url='/wd/hub/session'): Retry(total=0, connect=None, read=None, redirect=None, status=None) (retry.py:594)
2023-04-13 21:53:23 [ WARNING] Retrying (Retry(total=0, connect=None, read=None, redirect=None, status=None)) after connection broken by 'NewConnectionError('<urllib3.connection.HTTPConnection object at 0x1127d7c50>: Failed to establish a new connection: [Errno 61] Connection refused')': /wd/hub/session (connectionpool.py:813)
2023-04-13 21:53:23 [   DEBUG] Starting new HTTP connection (4): localhost:4444 (connectionpool.py:232)
2023-04-13 21:53:23 [   DEBUG] POST http://localhost:4444/wd/hub/session {"capabilities": {"firstMatch": [{}], "alwaysMatch": {"browserName": "chrome", "platformName": "any", "goog:chromeOptions": {"binary": "", "args": ["--window-size=1920,1080"]}}}} (remote_connection.py:303)
2023-04-13 21:53:23 [   DEBUG] Starting new HTTP connection (1): localhost:4444 (connectionpool.py:232)
2023-04-13 21:53:23 [   DEBUG] Incremented Retry for (url='/wd/hub/session'): Retry(total=2, connect=None, read=None, redirect=None, status=None) (retry.py:594)
2023-04-13 21:53:23 [ WARNING] Retrying (Retry(total=2, connect=None, read=None, redirect=None, status=None)) after connection broken by 'NewConnectionError('<urllib3.connection.HTTPConnection object at 0x112e71a50>: Failed to establish a new connection: [Errno 61] Connection refused')': /wd/hub/session (connectionpool.py:813)
2023-04-13 21:53:23 [   DEBUG] Starting new HTTP connection (2): localhost:4444 (connectionpool.py:232)
2023-04-13 21:53:23 [   DEBUG] Incremented Retry for (url='/wd/hub/session'): Retry(total=1, connect=None, read=None, redirect=None, status=None) (retry.py:594)
2023-04-13 21:53:23 [ WARNING] Retrying (Retry(total=1, connect=None, read=None, redirect=None, status=None)) after connection broken by 'NewConnectionError('<urllib3.connection.HTTPConnection object at 0x112e71fd0>: Failed to establish a new connection: [Errno 61] Connection refused')': /wd/hub/session (connectionpool.py:813)
2023-04-13 21:53:23 [   DEBUG] Starting new HTTP connection (3): localhost:4444 (connectionpool.py:232)
2023-04-13 21:53:23 [   DEBUG] Incremented Retry for (url='/wd/hub/session'): Retry(total=0, connect=None, read=None, redirect=None, status=None) (retry.py:594)
2023-04-13 21:53:23 [ WARNING] Retrying (Retry(total=0, connect=None, read=None, redirect=None, status=None)) after connection broken by 'NewConnectionError('<urllib3.connection.HTTPConnection object at 0x112c34cd0>: Failed to establish a new connection: [Errno 61] Connection refused')': /wd/hub/session (connectionpool.py:813)
2023-04-13 21:53:23 [   DEBUG] Starting new HTTP connection (4): localhost:4444 (connectionpool.py:232)
2023-04-13 21:53:23 [   DEBUG] POST http://localhost:4444/wd/hub/session {"capabilities": {"firstMatch": [{}], "alwaysMatch": {"browserName": "chrome", "platformName": "any", "goog:chromeOptions": {"binary": "", "args": ["--window-size=1920,1080"]}}}} (remote_connection.py:303)
2023-04-13 21:53:23 [   DEBUG] Starting new HTTP connection (1): localhost:4444 (connectionpool.py:232)
2023-04-13 21:53:23 [   DEBUG] Incremented Retry for (url='/wd/hub/session'): Retry(total=2, connect=None, read=None, redirect=None, status=None) (retry.py:594)
2023-04-13 21:53:23 [ WARNING] Retrying (Retry(total=2, connect=None, read=None, redirect=None, status=None)) after connection broken by 'NewConnectionError('<urllib3.connection.HTTPConnection object at 0x112c3c050>: Failed to establish a new connection: [Errno 61] Connection refused')': /wd/hub/session (connectionpool.py:813)
2023-04-13 21:53:23 [   DEBUG] Starting new HTTP connection (2): localhost:4444 (connectionpool.py:232)
2023-04-13 21:53:23 [   DEBUG] Incremented Retry for (url='/wd/hub/session'): Retry(total=1, connect=None, read=None, redirect=None, status=None) (retry.py:594)
2023-04-13 21:53:23 [ WARNING] Retrying (Retry(total=1, connect=None, read=None, redirect=None, status=None)) after connection broken by 'NewConnectionError('<urllib3.connection.HTTPConnection object at 0x112c3c910>: Failed to establish a new connection: [Errno 61] Connection refused')': /wd/hub/session (connectionpool.py:813)
2023-04-13 21:53:23 [   DEBUG] Starting new HTTP connection (3): localhost:4444 (connectionpool.py:232)
2023-04-13 21:53:23 [   DEBUG] Incremented Retry for (url='/wd/hub/session'): Retry(total=0, connect=None, read=None, redirect=None, status=None) (retry.py:594)
2023-04-13 21:53:23 [ WARNING] Retrying (Retry(total=0, connect=None, read=None, redirect=None, status=None)) after connection broken by 'NewConnectionError('<urllib3.connection.HTTPConnection object at 0x112c3ccd0>: Failed to establish a new connection: [Errno 61] Connection refused')': /wd/hub/session (connectionpool.py:813)
2023-04-13 21:53:23 [   DEBUG] Starting new HTTP connection (4): localhost:4444 (connectionpool.py:232)
2023-04-13 21:53:24 [   DEBUG] POST http://localhost:4444/wd/hub/session {"capabilities": {"firstMatch": [{}], "alwaysMatch": {"browserName": "chrome", "platformName": "any", "goog:chromeOptions": {"binary": "", "args": ["--window-size=1920,1080"]}}}} (remote_connection.py:303)
2023-04-13 21:53:24 [   DEBUG] Starting new HTTP connection (1): localhost:4444 (connectionpool.py:232)
2023-04-13 21:53:24 [   DEBUG] Incremented Retry for (url='/wd/hub/session'): Retry(total=2, connect=None, read=None, redirect=None, status=None) (retry.py:594)
2023-04-13 21:53:24 [ WARNING] Retrying (Retry(total=2, connect=None, read=None, redirect=None, status=None)) after connection broken by 'NewConnectionError('<urllib3.connection.HTTPConnection object at 0x112c47a10>: Failed to establish a new connection: [Errno 61] Connection refused')': /wd/hub/session (connectionpool.py:813)
2023-04-13 21:53:24 [   DEBUG] Starting new HTTP connection (2): localhost:4444 (connectionpool.py:232)
2023-04-13 21:53:24 [   DEBUG] Incremented Retry for (url='/wd/hub/session'): Retry(total=1, connect=None, read=None, redirect=None, status=None) (retry.py:594)
2023-04-13 21:53:24 [ WARNING] Retrying (Retry(total=1, connect=None, read=None, redirect=None, status=None)) after connection broken by 'NewConnectionError('<urllib3.connection.HTTPConnection object at 0x112c47f90>: Failed to establish a new connection: [Errno 61] Connection refused')': /wd/hub/session (connectionpool.py:813)
2023-04-13 21:53:24 [   DEBUG] Starting new HTTP connection (3): localhost:4444 (connectionpool.py:232)
2023-04-13 21:53:24 [   DEBUG] Incremented Retry for (url='/wd/hub/session'): Retry(total=0, connect=None, read=None, redirect=None, status=None) (retry.py:594)
2023-04-13 21:53:24 [ WARNING] Retrying (Retry(total=0, connect=None, read=None, redirect=None, status=None)) after connection broken by 'NewConnectionError('<urllib3.connection.HTTPConnection object at 0x112c4c890>: Failed to establish a new connection: [Errno 61] Connection refused')': /wd/hub/session (connectionpool.py:813)
2023-04-13 21:53:24 [   DEBUG] Starting new HTTP connection (4): localhost:4444 (connectionpool.py:232)
2023-04-13 21:53:24 [   DEBUG] POST http://localhost:4444/wd/hub/session {"capabilities": {"firstMatch": [{}], "alwaysMatch": {"browserName": "chrome", "platformName": "any", "goog:chromeOptions": {"binary": "", "args": ["--window-size=1920,1080"]}}}} (remote_connection.py:303)
2023-04-13 21:53:24 [   DEBUG] Starting new HTTP connection (1): localhost:4444 (connectionpool.py:232)
2023-04-13 21:53:24 [   DEBUG] Incremented Retry for (url='/wd/hub/session'): Retry(total=2, connect=None, read=None, redirect=None, status=None) (retry.py:594)
2023-04-13 21:53:24 [ WARNING] Retrying (Retry(total=2, connect=None, read=None, redirect=None, status=None)) after connection broken by 'NewConnectionError('<urllib3.connection.HTTPConnection object at 0x112c3c150>: Failed to establish a new connection: [Errno 61] Connection refused')': /wd/hub/session (connectionpool.py:813)
2023-04-13 21:53:24 [   DEBUG] Starting new HTTP connection (2): localhost:4444 (connectionpool.py:232)
2023-04-13 21:53:24 [   DEBUG] Incremented Retry for (url='/wd/hub/session'): Retry(total=1, connect=None, read=None, redirect=None, status=None) (retry.py:594)
2023-04-13 21:53:24 [ WARNING] Retrying (Retry(total=1, connect=None, read=None, redirect=None, status=None)) after connection broken by 'NewConnectionError('<urllib3.connection.HTTPConnection object at 0x112c0be50>: Failed to establish a new connection: [Errno 61] Connection refused')': /wd/hub/session (connectionpool.py:813)
2023-04-13 21:53:24 [   DEBUG] Starting new HTTP connection (3): localhost:4444 (connectionpool.py:232)
2023-04-13 21:53:24 [   DEBUG] Incremented Retry for (url='/wd/hub/session'): Retry(total=0, connect=None, read=None, redirect=None, status=None) (retry.py:594)
2023-04-13 21:53:24 [ WARNING] Retrying (Retry(total=0, connect=None, read=None, redirect=None, status=None)) after connection broken by 'NewConnectionError('<urllib3.connection.HTTPConnection object at 0x112e71e90>: Failed to establish a new connection: [Errno 61] Connection refused')': /wd/hub/session (connectionpool.py:813)
2023-04-13 21:53:24 [   DEBUG] Starting new HTTP connection (4): localhost:4444 (connectionpool.py:232)
2023-04-13 21:53:24 [   DEBUG] POST http://localhost:4444/wd/hub/session {"capabilities": {"firstMatch": [{}], "alwaysMatch": {"browserName": "chrome", "platformName": "any", "goog:chromeOptions": {"binary": "", "args": ["--window-size=1920,1080"]}}}} (remote_connection.py:303)
2023-04-13 21:53:24 [   DEBUG] Starting new HTTP connection (1): localhost:4444 (connectionpool.py:232)
2023-04-13 21:53:24 [   DEBUG] Incremented Retry for (url='/wd/hub/session'): Retry(total=2, connect=None, read=None, redirect=None, status=None) (retry.py:594)
2023-04-13 21:53:24 [ WARNING] Retrying (Retry(total=2, connect=None, read=None, redirect=None, status=None)) after connection broken by 'NewConnectionError('<urllib3.connection.HTTPConnection object at 0x112e7e690>: Failed to establish a new connection: [Errno 61] Connection refused')': /wd/hub/session (connectionpool.py:813)
2023-04-13 21:53:24 [   DEBUG] Starting new HTTP connection (2): localhost:4444 (connectionpool.py:232)
2023-04-13 21:53:24 [   DEBUG] Incremented Retry for (url='/wd/hub/session'): Retry(total=1, connect=None, read=None, redirect=None, status=None) (retry.py:594)
2023-04-13 21:53:24 [ WARNING] Retrying (Retry(total=1, connect=None, read=None, redirect=None, status=None)) after connection broken by 'NewConnectionError('<urllib3.connection.HTTPConnection object at 0x1127e5690>: Failed to establish a new connection: [Errno 61] Connection refused')': /wd/hub/session (connectionpool.py:813)
2023-04-13 21:53:24 [   DEBUG] Starting new HTTP connection (3): localhost:4444 (connectionpool.py:232)
2023-04-13 21:53:24 [   DEBUG] Incremented Retry for (url='/wd/hub/session'): Retry(total=0, connect=None, read=None, redirect=None, status=None) (retry.py:594)
2023-04-13 21:53:24 [ WARNING] Retrying (Retry(total=0, connect=None, read=None, redirect=None, status=None)) after connection broken by 'NewConnectionError('<urllib3.connection.HTTPConnection object at 0x1127e5250>: Failed to establish a new connection: [Errno 61] Connection refused')': /wd/hub/session (connectionpool.py:813)
2023-04-13 21:53:24 [   DEBUG] Starting new HTTP connection (4): localhost:4444 (connectionpool.py:232)
